<?xml version="1.0" encoding="UTF-8"?>
<testsuite name="DBTest" tests="1" skipped="0" failures="1" errors="0" timestamp="2016-02-15T11:25:26" hostname="PC" time="0.05">
  <properties/>
  <testcase name="insertShouldReturnInsert" classname="DBTest" time="0.05">
    <failure message="java.lang.AssertionError: inserting Lance should return Del Valle expected:&lt;Del Valle&gt; but was:&lt;null&gt;" type="java.lang.AssertionError">java.lang.AssertionError: inserting Lance should return Del Valle expected:&lt;Del Valle&gt; but was:&lt;null&gt;
	at org.junit.Assert.fail(Assert.java:88)
	at org.junit.Assert.failNotEquals(Assert.java:834)
	at org.junit.Assert.assertEquals(Assert.java:118)
	at DBTest.insertShouldReturnInsert(DBTest.java:35)
	at sun.reflect.NativeMethodAccessorImpl.invoke0(Native Method)
	at sun.reflect.NativeMethodAccessorImpl.invoke(NativeMethodAccessorImpl.java:62)
	at sun.reflect.DelegatingMethodAccessorImpl.invoke(DelegatingMethodAccessorImpl.java:43)
	at java.lang.reflect.Method.invoke(Method.java:497)
	at org.junit.runners.model.FrameworkMethod$1.runReflectiveCall(FrameworkMethod.java:50)
	at org.junit.internal.runners.model.ReflectiveCallable.run(ReflectiveCallable.java:12)
	at org.junit.runners.model.FrameworkMethod.invokeExplosively(FrameworkMethod.java:47)
	at org.junit.internal.runners.statements.InvokeMethod.evaluate(InvokeMethod.java:17)
	at org.junit.internal.runners.statements.FailOnTimeout$CallableStatement.call(FailOnTimeout.java:298)
	at org.junit.internal.runners.statements.FailOnTimeout$CallableStatement.call(FailOnTimeout.java:292)
	at java.util.concurrent.FutureTask.run(FutureTask.java:266)
	at java.lang.Thread.run(Thread.java:745)
</failure>
  </testcase>
  <system-out><![CDATA[]]></system-out>
  <system-err><![CDATA[]]></system-err>
</testsuite>
